<?xml version="1.0" ?>
<!-- Generated using onshape-to-robot -->
<!-- Onshape https://cad.onshape.com/documents/c20753502651006d91c30d21/w/7cd5bd1ae879168ec4a6eaf5/e/93debaac5a112231810bccfb -->
<robot name="pipebot">
  <!-- Link part_1 -->
  <link name="world">
  </link>

  <link name="part_1">
    <inertial>
      <origin xyz="-0.0226585 -4.33442e-19 0.100317" rpy="0 0 0"/>
      <mass value="2.23674"/>
      <inertia ixx="0.00590356" ixy="0" ixz="0.00249242" iyy="0.00797636" iyz="0" izz="0.00252015"/>
    </inertial>
    <!-- Part part_1 -->
    <visual>
      <origin xyz="0 0 0" rpy="0 -0 0"/>
      <geometry>
        <mesh filename="file://$(find pipebot)/pipebot/assets/part_1.stl"/>
      </geometry>
      <material name="part_1_material">
        <color rgba="0.647059 0.647059 0.647059 1.0"/>
      </material>
    </visual>
    <collision>
      <origin xyz="0 0 0" rpy="0 -0 0"/>
      <geometry>
        <mesh filename="file://$(find pipebot)/pipebot/assets/part_1.stl"/>
      </geometry>
    </collision>
  </link>
  <!-- Link part_2 -->
  <link name="part_2">
    <inertial>
      <origin xyz="3.6473e-19 0.0660276 -0.0964868" rpy="0 0 0"/>
      <mass value="2.77868"/>
      <inertia ixx="0.0153775" ixy="0" ixz="0" iyy="0.00469602" iyz="0.00507098" izz="0.0112372"/>
    </inertial>
    <!-- Part part_2 -->
    <visual>
      <origin xyz="-1.22465e-18 -0.151613 0.1" rpy="-1.5708 -1.5708 0"/>
      <geometry>
        <mesh filename="file://$(find pipebot)/pipebot/assets/part_2.stl"/>
      </geometry>
      <material name="part_2_material">
        <color rgba="0.917647 0.917647 0.917647 1.0"/>
      </material>
    </visual>
    <collision>
      <origin xyz="-1.22465e-18 -0.151613 0.1" rpy="-1.5708 -1.5708 0"/>
      <geometry>
        <mesh filename="file://$(find pipebot)/pipebot/assets/part_2.stl"/>
      </geometry>
    </collision>
  </link>
  <!-- Link part_3 -->
  <link name="part_3">
    <inertial>
      <origin xyz="0.0938264 -8.8827e-20 -0.0590008" rpy="0 0 0"/>
      <mass value="2.69207"/>
      <inertia ixx="0.00130357" ixy="-4.49705e-52" ixz="0.00212118" iyy="0.015358" iyz="0" izz="0.0145929"/>
    </inertial>
    <!-- Part part_3 -->
    <visual>
      <origin xyz="0.226011 1.22465e-18 0.342515" rpy="3.14159 -0 0"/>
      <geometry>
        <mesh filename="file://$(find pipebot)/pipebot/assets/part_3.stl"/>
      </geometry>
      <material name="part_3_material">
        <color rgba="0.768627 0.886275 0.952941 1.0"/>
      </material>
    </visual>
    <collision>
      <origin xyz="0.226011 1.22465e-18 0.342515" rpy="3.14159 -0 0"/>
      <geometry>
        <mesh filename="file://$(find pipebot)/pipebot/assets/part_3.stl"/>
      </geometry>
    </collision>
  </link>
  <!-- Joint from part_2 to part_3 -->
  <joint name="world_joint" type="fixed">
    <parent link="world"/>
    <child link="part_1"/>
  </joint>
  <joint name="rot_2" type="revolute">
    <origin xyz="3.85186e-34 0.190902 -0.126011" rpy="1.5708 -1.5708 0"/>
    <parent link="part_2"/>
    <child link="part_3"/>
    <axis xyz="0 0 1"/>
    <limit effort="10" velocity="10" lower="-3.141592653589793" upper="3.141592653589793"/>
  </joint>
  <!-- Joint from part_1 to part_2 -->
  <joint name="rot_1" type="revolute">
    <origin xyz="-0.1 1.22465e-18 0.151613" rpy="1.5708 -0 1.5708"/>
    <parent link="part_1"/>
    <child link="part_2"/>
    <axis xyz="0 0 1"/>
    <limit effort="10" velocity="10" lower="-3.141592653589793" upper="3.141592653589793"/>
  </joint>
</robot>
